<?xml version="1.0"?>
<robot  xmlns:xacro = "http:/www.ros.org/wiki/xacro">

    <link name="base_footprint"/>
    
    <link name="base_link">
        <visual>
            <geometry>
                <box size="0.3 0.2 0.01" />
            </geometry>
            <origin xyz="0 0 0.005" rpy="0 0 0" />
            <material name="blue" />
        </visual>
        <collision>
            <geometry>
                <box size="0.3 0.2 0.01" />
            </geometry>
            <origin xyz="0 0 0.005" rpy="0 0 0" />
        </collision>
        <xacro:box_inertia m="10.0" l="${2*0.3}" w="${16*0.2}" h="${2*0.01}"
                           xyz="0 0 0.005" rpy="0 0 0" />
    </link>

    <link name="right_wheel_link">
        <visual>
            <geometry>
                <cylinder radius="0.045" length="0.055" />
            </geometry>
            <origin xyz="0 0 0" rpy="${pi/2.0} 0 0" />
            <material name="grey" />
        </visual>
        <collision>
            <geometry>
                <sphere radius="0.045" />
            </geometry>
            <origin xyz="0 0 0" rpy="${pi/2.0} 0 0" />
        </collision>
        <xacro:cylinder_inertia m="0.5" r="${2*0.045}" h="${2*0.055}" 
                                xyz="0 0 0" rpy="${pi/2.0} 0 0" />
    </link>

    <link name="left_wheel_link">
        <visual>
            <geometry>
                <cylinder radius="0.045" length="0.055" />
            </geometry>
            <origin xyz="0 0 0" rpy="${pi/2.0} 0 0" />
            <material name="grey" />
        </visual>
        <collision>
            <geometry>
                <sphere radius="0.045"  />
            </geometry>
            <origin xyz="0 0 0" rpy="${pi/2.0} 0 0" />
        </collision>
        <xacro:cylinder_inertia m="0.5" r="${2*0.045}" h="${2*0.055}" 
                                xyz="0 0 0" rpy="${pi/2.0} 0 0" />
    </link>

    <link name="caster_wheel_link">
        <visual>
            <geometry>
                <sphere radius="0.025" />
            </geometry>
            <origin xyz="0 0 0" rpy="0 0 0" />
            <material name="grey" />
        </visual>
        <collision>
            <geometry>
                <sphere radius="0.025" />
            </geometry>
            <origin xyz="0 0 0" rpy="0 0 0" />
        </collision>
        <xacro:sphere_inertia m="0.5" r="${2*0.025}" xyz="0 0 0" rpy="0 0 0" />
    </link>

    <link name="axle_mount_link">
        <visual>
            <geometry>
                <cylinder radius="0.01" length="0.05" />
            </geometry>
            <origin xyz="0 0 0" rpy="0 0 0" />
            <material name="grey" />
        </visual>
        <collision>
            <geometry>
                <cylinder radius="0.01" length="0.05" />
            </geometry>
            <origin xyz="0 0 0" rpy="0 0 0" />
        </collision>
        <xacro:cylinder_inertia m="0.1" r="${2*0.01}" h="${2*0.05}" 
                                xyz="0 0 0" rpy="0 0 0" />
    </link>

    <link name="caster_mount_link">
        <visual>
            <geometry>
                <cylinder radius="0.01" length="0.075" />
            </geometry>
            <origin xyz="0 0 0" rpy="0 0 0" />
            <material name="grey" />
        </visual>
        <collision>
            <geometry>
                <cylinder radius="0.01" length="0.075" />
            </geometry>
            <origin xyz="0 0 0" rpy="0 0 0" />
        </collision>
        <xacro:cylinder_inertia m="0.1" r="${2*0.01}" h="${2*0.075}" 
                                xyz="0 0 0" rpy="0 0 0" />
    </link>

    <link name="axle_link">
        <visual>
            <geometry>
                <cylinder radius="0.01" length="0.17" />
            </geometry>
            <origin xyz="0 0 0" rpy="${pi/2.0} 0 0" />
            <material name="grey" />
        </visual>
        <collision>
            <geometry>
                <cylinder radius="0.01" length="0.17" />
            </geometry>
            <origin xyz="0 0 0" rpy="${pi/2.0} 0 0" />
        </collision>
        <xacro:cylinder_inertia m="0.1" r="${2*0.01}" h="${2*0.17}" 
                                xyz="0 0 0" rpy="${pi/2.0} 0 0" />
    </link>




<!-- joints section -->
    <joint name="base_joint" type="fixed">
        <parent link="base_footprint" />
        <child link="base_link" />
        <origin xyz="0 0 0.1" rpy="0 0 0"/>
    </joint>

    <joint name="axle_right_wheel_joint" type="continuous">
        <parent link="axle_link" />
        <child link="right_wheel_link" />
        <origin xyz="0 -0.116 0" rpy="0 0 0" />
        <axis xyz="0 1 0" />
    </joint>

    <joint name="axle_left_wheel_joint" type="continuous">
        <parent link="axle_link" />
        <child link="left_wheel_link" />
        <origin xyz="0 0.116 0" rpy="0 0 0" />
        <axis xyz="0 1 0" />
    </joint>

    <joint name="caster_mount_caster_wheel_joint" type="fixed">
        <parent link="caster_mount_link" />
        <child link="caster_wheel_link" />
        <origin xyz="0 0 -0.0375" rpy="0 0 0" />
    </joint>

    <joint name="base_axle_mount_joint" type="fixed">
        <parent link="base_link" />
        <child link="axle_mount_link" />
        <origin xyz="0.11 0 -0.025" rpy="0 0 0" />
    </joint>
    <joint name="base_caster_mount_joint" type="fixed">
        <parent link="base_link" />
        <child link="caster_mount_link" />
        <origin xyz="-0.11 0 -0.0375" rpy="0 0 0" />
    </joint>

    <joint name="axle_axle_mount_joint" type="fixed">
        <parent link="axle_mount_link" />
        <child link="axle_link" />
        <origin xyz="0 0 -0.030" rpy="0 0 0" />
    </joint>

   
    

        <!-- colors in gazebo world -->
    <gazebo reference="base_link">
        <material>Gazebo/Blue</material>
    </gazebo>

    <gazebo reference="right_wheel_link">
        <material>Gazebo/Grey</material>
    </gazebo>

    <gazebo reference="left_wheel_link">
        <material>Gazebo/Grey</material>
    </gazebo>

    <gazebo reference="caster_wheel_link">
        <material>Gazebo/Grey</material>
        <mu1 value = "0.001" />
        <mu2 value = "0.001" />
    </gazebo>

</robot>